Workbook

Sheet Tabela 1
A1: Parametr a | B1: Lp. | C1: x1(0) | D1: x2(0) | E1: Zewnętrzna funkcja kary | J1: Wewnętrzna funkcja kary
E2: x1* | F2: x2* | G2: r* | H2: y* | I2: Liczba wywołań funkcji celu | J2: x1* | K2: x2* | L2: r* | M2: y* | N2: Liczba wywołań funkcji celu
A3: 4 | B3: 1 | C3: 3.666776 | D3: 1.530444 | E3: 4.108182 | F3: 1.809741 | G3: 4.489134 | H3: -0.216992 | I3: 53 | J3: 3.505765 | K3: 1.738574 | L3: 3.913186 | M3: -0.178187 | N3: 95
B4: 2 | C4: 2.403333 | D4: 1.806526 | E4: 3.875012 | F4: 2.252815 | G4: 4.482287 | H4: -0.216988 | I4: 65 | J4: 3.247083 | K4: 2.150276 | L4: 3.894513 | M4: -0.175573 | N4: 54
B5: 3 | C5: 2.566517 | D5: 2.085667 | E5: 3.652455 | F5: 2.609105 | G5: 4.488636 | H5: -0.216992 | I5: 71 | J5: 3.246205 | K5: 2.140355 | L5: 3.888311 | M5: -0.174686 | N5: 60 | P5: {=a} -> #NAME?
B6: 4 | C6: 1.757119 | D6: 2.918684 | E6: 2.375527 | F6: 3.808577 | G6: 4.488696 | H6: -0.216992 | I6: 77 | J6: 2.324815 | K6: 3.150961 | L6: 3.915778 | M6: -0.178543 | N6: 90
B7: 5 | C7: 1.237197 | D7: 1.604342 | E7: 2.112197 | F7: 3.729342 | G7: 4.28595 | H7: -0.212344 | I7: 54 | J7: 1.893447 | K7: 3.323092 | L7: 3.824668 | M7: -0.165029 | N7: 54
B8: 6 | C8: 1.363172 | D8: 1.75221 | E8: 2.238172 | F8: 3.87721 | G8: 4.476848 | H8: -0.216976 | I8: 54 | J8: 1.514539 | K8: 3.604749 | L8: 3.909993 | M8: -0.177746 | N8: 59
B9: 7 | C9: 2.996176 | D9: 2.498037 | E9: 3.589926 | F9: 2.732412 | G9: 4.511501 | H9: -0.216937 | I9: 53 | J9: 2.761801 | K9: 2.763662 | L9: 3.907093 | M9: -0.177344 | N9: 64
B10: 8 | C10: 1.459862 | D10: 1.377843 | E10: 3.584862 | F10: 2.252843 | G10: 4.233974 | H10: -0.209613 | I10: 54 | J10: 3.178612 | K10: 2.034093 | L10: 3.77374 | M10: -0.156576 | N10: 54
B11: 9 | C11: 3.262344 | D11: 1.469068 | E11: 4.051406 | F11: 1.933912 | G11: 4.48931 | H11: -0.216992 | I11: 60 | J11: 3.512344 | K11: 1.594068 | L11: 3.857151 | M11: -0.170084 | N11: 41
B12: 10 | C12: 1.896293 | D12: 2.970712 | E12: 2.487113 | F12: 3.73829 | G12: 4.49005 | H12: -0.216992 | I12: 78 | J12: 2.127738 | K12: 3.288095 | L12: 3.916483 | M12: -0.178639 | N12: 53
B13: 11 | C13: 1.117876 | D13: 3.214161 | E13: 1.797564 | F13: 4.112599 | G13: 4.488285 | H13: -0.216992 | I13: 65 | J13: 1.97188 | K13: 3.374806 | L13: 3.90866 | M13: -0.177561 | N13: 95
B14: 12 | C14: 3.315733 | D14: 1.459023 | E14: 4.034483 | F14: 1.974648 | G14: 4.491802 | H14: -0.216991 | I14: 71 | J14: 3.565733 | K14: 1.584023 | L14: 3.901741 | M14: -0.176595 | N14: 41
B15: 13 | C15: 1.835121 | D15: 2.22846 | E15: 2.171058 | F15: 3.923772 | G15: 4.48436 | H15: -0.21699 | I15: 65 | J15: 2.558571 | K15: 2.965973 | L15: 3.91705 | M15: -0.178717 | N15: 77
B16: 14 | C16: 2.507389 | D16: 2.408717 | E16: 3.394108 | F16: 2.936061 | G16: 4.487808 | H16: -0.216992 | I16: 66 | J16: 2.758832 | K16: 2.777748 | L16: 3.914976 | M16: -0.178433 | N16: 120
B17: 15 | C17: 1.605887 | D17: 2.35119 | E17: 1.941824 | F17: 4.046502 | G17: 4.488303 | H17: -0.216992 | I17: 65 | J17: 2.313742 | K17: 3.158593 | L17: 3.915369 | M17: -0.178487 | N17: 88
... B102: 100 | C102: 1.565652 | D102: 2.677269 | E102: 2.253152 | F102: 3.864769 | G102: 4.473605 | H102: -0.216967 | I102: 53 | J102: 1.99534 | K102: 3.349144 | L102: 3.89848 | M102: -0.176136 | N102: 60
A103: avg | E103: =AVERAGE(E3:E102) -> 2.8945397 | F103: =AVERAGE(F3:F102) -> 3.1308198 | G103: =AVERAGE(G3:G102) -> 4.4495766 | H103: =AVERAGE(H3:H102) -> -0.21615624 | I103: =AVERAGE(I3:I102) -> 63.3 | J103: =AVERAGE(J3:J102) -> 2.6139913 | K103: =AVERAGE(K3:K102) -> 2.7158304 | L103: =AVERAGE(L3:L102) -> 3.8869403 | ... N103: =AVERAGE(N3:N102) -> 63.58
A104: 4.4934 | B104: 1 | C104: 3.881378 | D104: 1.285309 | E104: 4.223175 | F104: 1.541168 | G104: 4.495598 | H104: -0.217233 | I104: 53 | J104: 4.006378 | K104: 1.597809 | L104: 4.313242 | M104: -0.21362 | N104: 40
B105: 2 | C105: 1.688497 | D105: 1.386111 | E105: 3.813497 | F105: 2.261111 | G105: 4.433439 | H105: -0.21684 | I105: 54 | J105: 3.610372 | K105: 2.151736 | L105: 4.202946 | M105: -0.207715 | N105: 54
B106: 3 | C106: 2.357736 | D106: 1.032522 | E106: 4.076486 | F106: 1.688772 | G106: 4.412447 | H106: -0.216513 | I106: 53 | J106: 4.019845 | K106: 1.58135 | L106: 4.319702 | M106: -0.213877 | N106: 66
B107: 4 | C107: 3.559512 | D107: 1.82618 | E107: 3.973575 | F107: 2.087899 | G107: 4.488721 | H107: -0.217231 | I107: 47 | J107: 3.840762 | K107: 1.98243 | L107: 4.322208 | M107: -0.213974 | N107: 36
B108: 5 | C108: 1.972412 | D108: 1.497179 | E108: 3.691162 | F108: 2.153429 | G108: 4.273398 | H108: -0.211818 | I108: 54 | J108: 3.691162 | K108: 2.153429 | L108: 4.273398 | M108: -0.211818 | N108: 54
B109: 6 | C109: 2.068122 | D109: 2.761708 | E109: 2.765392 | F109: 3.541756 | G109: 4.493487 | H109: -0.217234 | I109: 101 | J109: 2.380622 | K109: 3.574208 | L109: 4.294453 | M109: -0.212816 | N109: 53
B110: 7 | C110: 4.154394 | D110: 1.668814 | E110: 4.10845 | F110: 1.81848 | G110: 4.492908 | H110: -0.217234 | I110: 71 | J110: 3.889745 | K110: 1.904165 | L110: 4.330816 | M110: -0.214297 | N110: 65
B111: 8 | C111: 2.197727 | D111: 2.621775 | E111: 2.771275 | F111: 3.536631 | G111: 4.493075 | H111: -0.217234 | I111: 101 | J111: 2.557102 | K111: 3.48115 | L111: 4.319396 | M111: -0.213865 | N111: 54
B112: 9 | C112: 3.450905 | D112: 2.709949 | E112: 3.49778 | F112: 2.819324 | G112: 4.492555 | H112: -0.217234 | I112: 52 | J112: 3.18528 | K112: 2.944324 | L112: 4.337632 | M112: -0.21454 | N112: 59
B113: 10 | C113: 3.284829 | D113: 1.823503 | E113: 3.927407 | F113: 2.177018 | G113: 4.490427 | H113: -0.217233 | I113: 65 | J113: 3.795571 | K113: 2.083756 | L113: 4.329942 | M113: -0.214265 | N113: 71
B114: 11 | C114: 2.533386 | D114: 1.363441 | E114: 4.093933 | F114: 1.857582 | G114: 4.495653 | H114: -0.217233 | I114: 65 | J114: 3.783386 | K114: 2.113441 | L114: 4.333664 | M114: -0.2144 | N114: 48
B115: 12 | C115: 3.396139 | D115: 2.057916 | E115: 3.841451 | F115: 2.33526 | G115: 4.495574 | H115: -0.217233 | I115: 53 | J115: 3.693014 | K115: 2.229791 | L115: 4.313968 | M115: -0.213649 | N115: 42
B116: 13 | C116: 2.75569 | D116: 1.410606 | E116: 3.94319 | F116: 2.098106 | G116: 4.466631 | H116: -0.217155 | I116: 53 | J116: 3.888503 | K116: 1.855918 | L116: 4.308699 | M116: -0.213433 | N116: 59
... B203: 100 | C203: 2.323214 | D203: 2.837561 | E203: 2.479464 | F203: 3.743811 | G203: 4.490419 | H203: -0.217233 | I203: 53 | J203: 2.979464 | K203: 3.150061 | L203: 4.335907 | M203: -0.21448 | N203: 66
E204: =AVERAGE(E104:E203) -> 3.0495607 | F204: =AVERAGE(F104:F203) -> 3.0356141 | G204: =AVERAGE(G104:G203) -> 4.4707581 | H204: =AVERAGE(H104:H203) -> -0.21679664 | I204: =AVERAGE(I104:I203) -> 59.6 | J204: =AVERAGE(J104:J203) -> 2.8957221 | K204: =AVERAGE(K104:K203) -> 2.993272 | L204: =AVERAGE(L104:L203) -> 4.3022176 | ... N204: =AVERAGE(N104:N203) -> 61.48
A205: 5 | B205: 1 | C205: 1.910644 | D205: 3.809114 | E205: 2.184082 | F205: 3.926301 | G205: 4.492889 | H205: -0.217234 | I205: 48 | J205: 2.302246 | K205: 3.838411 | L205: 4.475906 | M205: -0.2172 | N205: 60
B206: 2 | C206: 3.787354 | D206: 2.519024 | E206: 3.538086 | F206: 2.769756 | G206: 4.493284 | H206: -0.217234 | I206: 84 | J206: 3.382568 | K206: 2.926738 | L206: 4.472982 | M206: -0.217188 | N206: 83
B207: 3 | C207: 2.07317 | D207: 4.205789 | E207: 2.299733 | F207: 3.869851 | G207: 4.501613 | H207: -0.217226 | I207: 47 | J207: 2.495045 | K207: 3.752664 | L207: 4.506411 | M207: -0.217215 | N207: 53
B208: 4 | C208: 2.567452 | D208: 3.15079 | E208: 2.75483 | F208: 3.550082 | G208: 4.49357 | H208: -0.217234 | I208: 99 | J208: 2.879464 | K208: 3.435458 | L208: 4.482598 | M208: -0.217221 | N208: 65
B209: 5 | C209: 1.858756 | D209: 2.85833 | E209: 2.477164 | F209: 3.748223 | G209: 4.492829 | H209: -0.217234 | I209: 89 | J209: 2.831412 | K209: 3.471612 | L209: 4.479842 | M209: -0.217214 | N209: 111
B210: 6 | C210: 1.706049 | D210: 2.741148 | E210: 2.237299 | F210: 3.897398 | G210: 4.493909 | H210: -0.217234 | I210: 53 | J210: 2.299799 | K210: 3.834898 | L210: 4.471635 | M210: -0.217182 | N210: 59
...

Sheet Tabela 2
A1: Parametr a | B1: Zewnętrzna funkcja kary | G1: Wewnętrzna funkcja kary
B2: x1* | C2: x2* | D2: r* | E2: y* | F2: Liczba wywołań funkcji celu | G2: x1* | H2: x2* | I2: r* | J2: y* | K2: Liczba wywołań funkcji celu
A3: 4 | B3: ='Tabela 1'!E103 -> 2.8945397 | C3: ='Tabela 1'!F103 -> 3.1308198 | D3: ='Tabela 1'!G103 -> 4.4495766 | E3: ='Tabela 1'!H103 -> -0.21615624 | F3: ='Tabela 1'!I103 -> 63.3 | G3: ='Tabela 1'!J103 -> 2.6139913 | H3: ='Tabela 1'!K103 -> 2.7158304 | I3: ='Tabela 1'!L103 -> 3.8869403 | ... K3: ='Tabela 1'!N103 -> 63.58
A4: 4.4934 | B4: ='Tabela 1'!E204 -> 3.0495607 | C4: ='Tabela 1'!F204 -> 3.0356141 | D4: ='Tabela 1'!G204 -> 4.4707581 | E4: ='Tabela 1'!H204 -> -0.21679664 | F4: ='Tabela 1'!I204 -> 59.6 | G4: ='Tabela 1'!J204 -> 2.8957221 | H4: ='Tabela 1'!K204 -> 2.993272 | I4: ='Tabela 1'!L204 -> 4.3022176 | ... K4: ='Tabela 1'!N204 -> 61.48
A5: 5 | B5: ='Tabela 1'!E305 -> 2.9763284 | C5: ='Tabela 1'!F305 -> 3.1659372 | D5: ='Tabela 1'!G305 -> 4.4852304 | E5: ='Tabela 1'!H305 -> -0.21707272 | F5: ='Tabela 1'!I305 -> 62.07 | G5: ='Tabela 1'!J305 -> 2.9727944 | H5: ='Tabela 1'!K305 -> 3.1939547 | I5: ='Tabela 1'!L305 -> 4.4848383 | ... K5: ='Tabela 1'!N305 -> 62.36

Sheet Tabela 3
A1: v0x(0) | B1: ω(0) | C1: v0x* | D1: ω* | E1: xend* | F1: x* dla y = 50m | G1: Liczba wywołań funkcji celu
A2: 0 | B2: 9.5 | C2: 0 | D2: 9.6 | E2: 21.972222 | F2: 6.957002 | G2: 70 | K2: x0_1 | L2: x0_2 | M2: sol_x1 | N2: sol_x2 | Q2: x0_1 | R2: x0_2 | S2: sol_x1 | T2: sol_x2
K3: -10 | L3: -10 | M3: -7.0625 | N3: -8.6875 | Q3: 0 | R3: 0 | S3: 2.9375 | T3: 1.3125 | U3: 0 | V3: 0 | W3: 2.9375 | X3: 1.3125
K4: -9.75 | L4: -9.75 | M4: -6.8125 | N4: -8.4375 | Q4: 0.5 | R4: 0.5 | S4: 3.4375 | T4: 1.8125 | U4: 0.5 | V4: 0.5 | W4: 3.4375 | X4: 1.8125
K5: -9.5 | L5: -9.5 | M5: -6.5625 | N5: -8.1875 | Q5: 1 | R5: 1 | S5: 3.792969 | T5: 2.503906 | U5: 1 | V5: 1 | W5: 3.792969 | X5: 2.503906
K6: -9.25 | L6: -9.25 | M6: -6.3125 | N6: -7.9375 | Q6: 1.5 | R6: 1.5 | S6: 3.859375 | T6: 3.578125 | U6: 1.5 | V6: 1.5 | W6: 3.859375 | X6: 3.578125
K7: -9 | L7: -9 | M7: -6.0625 | N7: -7.6875 | Q7: 2 | R7: 2 | S7: 3.34375 | T7: 3.53125 | U7: 2 | V7: 2 | W7: 3.34375 | X7: 3.53125
K8: -8.75 | L8: -8.75 | M8: -5.8125 | N8: -7.4375 | Q8: 2.5 | R8: 2.5 | S8: 3.375 | T8: 4.625
K9: -8.5 | L9: -8.5 | M9: -5.5625 | N9: -7.1875 | Q9: 3 | R9: 3 | S9: 3.523438 | T9: 5.007812
K10: -8.25 | L10: -8.25 | M10: -5.3125 | N10: -6.9375
K11: -8 | L11: -8 | M11: -5.0625 | N11: -6.6875
K12: -7.75 | L12: -7.75 | M12: -4.8125 | N12: -6.4375
K13: -7.5 | L13: -7.5 | M13: -4.5625 | N13: -6.1875
K14: -7.25 | L14: -7.25 | M14: -4.3125 | N14: -5.9375
K15: -7 | L15: -7 | M15: -4.0625 | N15: -5.6875
K16: -6.75 | L16: -6.75 | M16: -3.8125 | N16: -5.4375
K17: -6.5 | L17: -6.5 | M17: -3.5625 | N17: -5.1875
K18: -6.25 | L18: -6.25 | M18: -3.3125 | N18: -4.9375
K19: -6 | L19: -6 | M19: -3.0625 | N19: -4.6875
K20: -5.75 | L20: -5.75 | M20: -2.8125 | N20: -4.4375
K21: -5.5 | L21: -5.5 | M21: -2.5625 | N21: -4.1875
... K78: 10 | L78: 10 | M78: 8.5 | N78: 10.125

Sheet Symulacja
A1: t | B1: x | C1: y
A2: 0 | B2: 0 | C2: 100
A3: 0.01 | B3: 0 | C3: 99.99951
A4: 0.02 | B4: 1e-06 | C4: 99.998038
A5: 0.03 | B5: 5e-06 | C5: 99.995586
A6: 0.04 | B6: 1.1e-05 | C6: 99.992152
A7: 0.05 | B7: 2.1e-05 | C7: 99.987739
A8: 0.06 | B8: 3.7e-05 | C8: 99.982344
A9: 0.07 | B9: 5.8e-05 | C9: 99.975969
A10: 0.08 | B10: 8.7e-05 | C10: 99.968615
A11: 0.09 | B11: 0.000124 | C11: 99.96028
A12: 0.1 | B12: 0.00017 | C12: 99.950967
A13: 0.11 | B13: 0.000227 | C13: 99.940674
... A610: 6.08 | B610: 21.972222 | C610: 0.04558
