Workbook

Sheet Tabela 1
A1: Długość kroku | B1: Lp. | C1: x1(0) | D1: x2(0) | E1: Metoda najszybszego spadku | K1: Metoda gradientów sprzężonych | Q1: Metoda Newtona
E2: x1* | F2: x2* | G2: y* | H2: f_calls | I2: g_calls | J2: Minimum globalne [TAK/NIE] | K2: x1* | L2: x2* | M2: y* | N2: f_calls | O2: g_calls | P2: Minimum globalne [TAK/NIE] | Q2: x1* | R2: x2* | S2: y* | T2: f_calls | U2: g_calls | V2: H_calls | W2: Minimum globalne [TAK/NIE]
A3: 0.05 | B3: 1 | C3: 1.830541 | D3: 0.299069 | E3: 1.746693 | F3: -0.864992 | G3: 0.298713 | H3: 1 | I3: 49 | J3: =IF(ABS(G3) < 0.01,"TAK","NIE") -> NIE | K3: 1.747415 | L3: -0.871944 | M3: 0.298642 | N3: 1 | O3: 55 | P3: =IF(ABS(M3) < 0.01,"TAK","NIE") -> NIE | Q3: 1.749176 | R3: -0.855535 | S3: 0.299017 | T3: 1 | U3: 81 | V3: 81 | W3: =IF(ABS(S3) < 0.01,"TAK","NIE") -> NIE
B4: 2 | C4: 1.434883 | D4: 1.230764 | E4: 1.746682 | F4: -0.864883 | G4: 0.298714 | H4: 1 | I4: 57 | J4: =IF(ABS(G4) < 0.01,"TAK","NIE") -> NIE | K4: nan | L4: nan | M4: nan | N4: 1 | O4: 43 | P4: =IF(ABS(M4) < 0.01,"TAK","NIE") -> #VALUE! | Q4: 1.073367 | R4: -0.517419 | S4: 0.877715 | T4: 1 | U4: 90 | V4: 90 | W4: =IF(ABS(S4) < 0.01,"TAK","NIE") -> NIE
B5: 3 | C5: 0.951744 | D5: 1.596003 | E5: -0.004184 | F5: 0.010108 | G5: 9.5e-05 | H5: 1 | I5: 54 | J5: =IF(ABS(G5) < 0.01,"TAK","NIE") -> TAK | K5: 4e-05 | L5: 0.001106 | M5: 1e-06 | N5: 1 | O5: 64 | P5: =IF(ABS(M5) < 0.01,"TAK","NIE") -> TAK | Q5: 1.069593 | R5: -0.517231 | S5: 0.877668 | T5: 1 | U5: 93 | V5: 93 | W5: =IF(ABS(S5) < 0.01,"TAK","NIE") -> NIE
B6: 4 | C6: 0.176069 | D6: 0.705197 | E6: -0.004239 | F6: 0.010239 | G6: 9.7e-05 | H6: 1 | I6: 48 | J6: =IF(ABS(G6) < 0.01,"TAK","NIE") -> TAK | K6: -2.9e-05 | L6: 0.00124 | M6: 2e-06 | N6: 1 | O6: 58 | P6: =IF(ABS(M6) < 0.01,"TAK","NIE") -> TAK | Q6: 0.004208 | R6: 0.017643 | S6: 0.000421 | T6: 1 | U6: 72 | V6: 72 | W6: =IF(ABS(S6) < 0.01,"TAK","NIE") -> TAK
B7: 5 | C7: 1.33676 | D7: 1.031001 | E7: 1.74671 | F7: -0.865164 | G7: 0.29871 | H7: 1 | I7: 69 | J7: =IF(ABS(G7) < 0.01,"TAK","NIE") -> NIE | K7: nan | L7: nan | M7: nan | N7: 1 | O7: 58 | P7: =IF(ABS(M7) < 0.01,"TAK","NIE") -> #VALUE! | Q7: 1.073375 | R7: -0.517088 | S7: 0.877728 | T7: 1 | U7: 87 | V7: 87 | W7: =IF(ABS(S7) < 0.01,"TAK","NIE") -> NIE
B8: 6 | C8: 0.728487 | D8: 0.058684 | E8: 0.004345 | F8: -0.010377 | G8: 0.0001 | H8: 1 | I8: 41 | J8: =IF(ABS(G8) < 0.01,"TAK","NIE") -> TAK | K8: -0.001057 | L8: -0.000144 | M8: 2e-06 | N8: 1 | O8: 46 | P8: =IF(ABS(M8) < 0.01,"TAK","NIE") -> TAK | Q8: 1.062811 | R8: -0.518479 | S8: 0.877398 | T8: 1 | U8: 68 | V8: 68 | W8: =IF(ABS(S8) < 0.01,"TAK","NIE") -> NIE
B9: 7 | C9: 0.998412 | D9: 1.406785 | E9: -0.004297 | F9: 0.010396 | G9: 0.0001 | H9: 1 | I9: 50 | J9: =IF(ABS(G9) < 0.01,"TAK","NIE") -> TAK | K9: -0.001303 | L9: 0.00237 | M9: 6e-06 | N9: 1 | O9: 52 | P9: =IF(ABS(M9) < 0.01,"TAK","NIE") -> TAK | Q9: 1.069885 | R9: -0.517038 | S9: 0.877681 | T9: 1 | U9: 91 | V9: 91 | W9: =IF(ABS(S9) < 0.01,"TAK","NIE") -> NIE
B10: 8 | C10: 1.856469 | D10: 1.410862 | E10: 1.746685 | F10: -0.864909 | G10: 0.298714 | H10: 1 | I10: 56 | J10: =IF(ABS(G10) < 0.01,"TAK","NIE") -> NIE | K10: nan | L10: nan | M10: nan | N10: 1 | O10: 46 | P10: =IF(ABS(M10) < 0.01,"TAK","NIE") -> #VALUE! | Q10: 1.748723 | R10: -0.855522 | S10: 0.299001 | T10: 1 | U10: 94 | V10: 94 | W10: =IF(ABS(S10) < 0.01,"TAK","NIE") -> NIE
B11: 9 | C11: 0.230818 | D11: 0.356198 | E11: -0.004271 | F11: 0.010402 | G11: 0.0001 | H11: 1 | I11: 37 | J11: =IF(ABS(G11) < 0.01,"TAK","NIE") -> TAK | K11: -0.00106 | L11: 0.002717 | M11: 7e-06 | N11: 1 | O11: 46 | P11: =IF(ABS(M11) < 0.01,"TAK","NIE") -> TAK | Q11: 0.009413 | R11: 0.015934 | S11: 0.000581 | T11: 1 | U11: 61 | V11: 61 | W11: =IF(ABS(S11) < 0.01,"TAK","NIE") -> TAK
B12: 10 | C12: 1.82403 | D12: 1.436731 | E12: 1.746672 | F12: -0.864781 | G12: 0.298716 | H12: 1 | I12: 56 | J12: =IF(ABS(G12) < 0.01,"TAK","NIE") -> NIE | K12: nan | L12: #NAME? | M12: nan | N12: 1 | O12: 46 | P12: =IF(ABS(M12) < 0.01,"TAK","NIE") -> #VALUE! | Q12: 1.748309 | R12: -0.855237 | S12: 0.299 | T12: 1 | U12: 94 | V12: 94 | W12: =IF(ABS(S12) < 0.01,"TAK","NIE") -> NIE
B13: 11 | C13: 0.972829 | D13: 0.771838 | E13: -0.001101 | F13: 0.008365 | G13: 6.3e-05 | H13: 1 | I13: 28 | J13: =IF(ABS(G13) < 0.01,"TAK","NIE") -> TAK | K13: 2.3e-05 | L13: -0.001467 | M13: 2e-06 | N13: 1 | O13: 52 | P13: =IF(ABS(M13) < 0.01,"TAK","NIE") -> TAK | Q13: 1.06922 | R13: -0.516793 | S13: 0.877675 | T13: 1 | U13: 83 | V13: 83 | W13: =IF(ABS(S13) < 0.01,"TAK","NIE") -> NIE
B14: 12 | C14: 0.157517 | D14: 1.400876 | E14: -0.004295 | F14: 0.010368 | G14: 0.0001 | H14: 1 | I14: 57 | J14: =IF(ABS(G14) < 0.01,"TAK","NIE") -> TAK | K14: -0.000245 | L14: 0.001639 | M14: 2e-06 | N14: 1 | O14: 61 | P14: =IF(ABS(M14) < 0.01,"TAK","NIE") -> TAK | Q14: 0.002051 | R14: 0.018878 | S14: 0.000404 | T14: 1 | U14: 84 | V14: 84 | W14: =IF(ABS(S14) < 0.01,"TAK","NIE") -> TAK
B15: 13 | C15: 0.719356 | D15: 1.164407 | E15: -0.004183 | F15: 0.010109 | G15: 9.5e-05 | H15: 1 | I15: 51 | J15: =IF(ABS(G15) < 0.01,"TAK","NIE") -> TAK | K15: 6.5e-05 | L15: 0.001374 | M15: 2e-06 | N15: 1 | O15: 61 | P15: =IF(ABS(M15) < 0.01,"TAK","NIE") -> TAK | Q15: 1.067741 | R15: -0.517172 | S15: 0.877623 | T15: 1 | U15: 88 | V15: 88 | W15: =IF(ABS(S15) < 0.01,"TAK","NIE") -> NIE
B16: 14 | C16: 1.417619 | D16: 0.980767 | E16: 1.746663 | F16: -0.864692 | G16: 0.298718 | H16: 1 | I16: 55 | J16: =IF(ABS(G16) < 0.01,"TAK","NIE") -> NIE | K16: 1.747597 | L16: -0.875739 | M16: 0.298642 | N16: 1 | O16: 64 | P16: =IF(ABS(M16) < 0.01,"TAK","NIE") -> NIE | Q16: 1.073812 | R16: -0.51742 | S16: 0.877718 | T16: 1 | U16: 87 | V16: 87 | W16: =IF(ABS(S16) < 0.01,"TAK","NIE") -> NIE
B17: 15 | C17: 0.709673 | D17: 1.37562 | E17: -0.00418 | F17: 0.010095 | G17: 9.5e-05 | H17: 1 | I17: 54 | J17: =IF(ABS(G17) < 0.01,"TAK","NIE") -> TAK | K17: 6.8e-05 | L17: 0.001583 | M17: 3e-06 | N17: 1 | O17: 61 | P17: =IF(ABS(M17) < 0.01,"TAK","NIE") -> TAK | Q17: 1.067985 | R17: -0.516881 | S17: 0.87764 | T17: 1 | U17: 90 | V17: 90 | W17: =IF(ABS(S17) < 0.01,"TAK","NIE") -> NIE
B18: 16 | C18: 0.094198 | D18: 1.659396 | E18: -0.004095 | F18: 0.009885 | G18: 9.1e-05 | H18: 1 | I18: 60 | J18: =IF(ABS(G18) < 0.01,"TAK","NIE") -> TAK | K18: -0.000229 | L18: 0.001834 | M18: 3e-06 | N18: 1 | O18: 61 | P18: =IF(ABS(M18) < 0.01,"TAK","NIE") -> TAK | Q18: 0.00102 | R18: 0.018187 | S18: 0.000351 | T18: 1 | U18: 88 | V18: 88 | W18: =IF(ABS(S18) < 0.01,"TAK","NIE") -> TAK
B19: 17 | C19: 1.439587 | D19: 1.412103 | E19: 1.746661 | F19: -0.864673 | G19: 0.298718 | H19: 1 | I19: 59 | J19: =IF(ABS(G19) < 0.01,"TAK","NIE") -> NIE | K19: nan | L19: nan | M19: nan | N19: 1 | O19: 46 | P19: =IF(ABS(M19) < 0.01,"TAK","NIE") -> #VALUE! | Q19: 1.073223 | R19: -0.516585 | S19: 0.877747 | T19: 1 | U19: 91 | V19: 91 | W19: =IF(ABS(S19) < 0.01,"TAK","NIE") -> NIE
B20: 18 | C20: 1.551422 | D20: 1.597242 | E20: 1.746692 | F20: -0.864984 | G20: 0.298713 | H20: 1 | I20: 58 | J20: =IF(ABS(G20) < 0.01,"TAK","NIE") -> NIE | K20: nan | L20: nan | M20: nan | N20: 1 | O20: 46 | P20: =IF(ABS(M20) < 0.01,"TAK","NIE") -> #VALUE! | Q20: 1.746759 | R20: -0.855223 | S20: 0.298972 | T20: 1 | U20: 95 | V20: 95 | W20: =IF(ABS(S20) < 0.01,"TAK","NIE") -> NIE
B21: 19 | C21: 0.829402 | D21: 0.157317 | E21: 0.004169 | F21: -0.009941 | G21: 9.2e-05 | H21: 1 | I21: 42 | J21: =IF(ABS(G21) < 0.01,"TAK","NIE") -> TAK | K21: 0.00033 | L21: 0.000786 | M21: 1e-06 | N21: 1 | O21: 64 | P21: =IF(ABS(M21) < 0.01,"TAK","NIE") -> TAK | Q21: 1.06521 | R21: -0.517616 | S21: 0.877524 | T21: 1 | U21: 71 | V21: 71 | W21: =IF(ABS(S21) < 0.01,"TAK","NIE") -> NIE
B22: 20 | C22: 1.518182 | D22: 1.500765 | E22: 1.746626 | F22: -0.864317 | G22: 0.298724 | H22: 1 | I22: 57 | J22: =IF(ABS(G22) < 0.01,"TAK","NIE") -> NIE | K22: nan | L22: #NAME? | M22: nan | N22: 1 | O22: 43 | P22: =IF(ABS(M22) < 0.01,"TAK","NIE") -> #VALUE! | Q22: 1.74672 | R22: -0.855159 | S22: 0.298974 | T22: 1 | U22: 94 | V22: 94 | W22: =IF(ABS(S22) < 0.01,"TAK","NIE") -> NIE
B23: 21 | C23: 0.153552 | D23: 1.953646 | E23: -0.004419 | F23: 0.010667 | G23: 0.000106 | H23: 1 | I23: 61 | J23: =IF(ABS(G23) < 0.01,"TAK","NIE") -> TAK | K23: -0.000118 | L23: 0.00129 | M23: 2e-06 | N23: 1 | O23: 64 | P23: =IF(ABS(M23) < 0.01,"TAK","NIE") -> TAK | Q23: 0.001399 | R23: 0.018374 | S23: 0.000367 | T23: 1 | U23: 91 | V23: 91 | W23: =IF(ABS(S23) < 0.01,"TAK","NIE") -> TAK
B24: 22 | C24: 1.645366 | D24: 1.836772 | E24: 1.746713 | F24: -0.865196 | G24: 0.298709 | H24: 1 | I24: 59 | J24: =IF(ABS(G24) < 0.01,"TAK","NIE") -> NIE | K24: nan | L24: #NAME? | M24: nan | N24: 1 | O24: 46 | P24: =IF(ABS(M24) < 0.01,"TAK","NIE") -> #VALUE! | Q24: 1.747033 | R24: -0.855152 | S24: 0.298977 | T24: 1 | U24: 97 | V24: 97 | W24: =IF(ABS(S24) < 0.01,"TAK","NIE") -> NIE
B25: 23 | C25: 0.115956 | D25: 0.094619 | E25: -0.002205 | F25: 0.009556 | G25: 8e-05 | H25: 1 | I25: 18 | J25: =IF(ABS(G25) < 0.01,"TAK","NIE") -> TAK | K25: -0.000849 | L25: 0.000667 | M25: 1e-06 | N25: 1 | O25: 40 | P25: =IF(ABS(M25) < 0.01,"TAK","NIE") -> TAK | Q25: 0.013914 | R25: 0.011673 | S25: 0.000686 | T25: 1 | U25: 41 | V25: 41 | W25: =IF(ABS(S25) < 0.01,"TAK","NIE") -> TAK
B26: 24 | C26: 1.623803 | D26: 0.270058 | E26: 1.746692 | F26: -0.864986 | G26: 0.298713 | H26: 1 | I26: 49 | J26: =IF(ABS(G26) < 0.01,"TAK","NIE") -> NIE | K26: 1.747265 | L26: -0.871923 | M26: 0.298642 | N26: 1 | O26: 55 | P26: =IF(ABS(M26) < 0.01,"TAK","NIE") -> NIE | Q26: 1.746147 | R26: -0.855205 | S26: 0.298969 | T26: 1 | U26: 80 | V26: 80 | W26: =IF(ABS(S26) < 0.01,"TAK","NIE") -> NIE
B27: 25 | C27: 1.040054 | D27: 1.531932 | E27: -0.004334 | F27: 0.010481 | G27: 0.000102 | H27: 1 | I27: 51 | J27: =IF(ABS(G27) < 0.01,"TAK","NIE") -> TAK | K27: -0.001374 | L27: 0.002297 | M27: 6e-06 | N27: 1 | O27: 52 | P27: =IF(ABS(M27) < 0.01,"TAK","NIE") -> TAK | Q27: 1.070273 | R27: -0.516824 | S27: 0.877697 | T27: 1 | U27: 92 | V27: 92 | W27: =IF(ABS(S27) < 0.01,"TAK","NIE") -> NIE
B28: 26 | C28: 0.454813 | D28: 1.360636 | E28: -0.004378 | F28: 0.01057 | G28: 0.000104 | H28: 1 | I28: 55 | J28: =IF(ABS(G28) < 0.01,"TAK","NIE") -> TAK | K28: -1.1e-05 | L28: 0.001537 | M28: 2e-06 | N28: 1 | O28: 61 | P28: =IF(ABS(M28) < 0.01,"TAK","NIE") -> TAK | Q28: 0.004293 | R28: 0.018147 | S28: 0.000444 | T28: 1 | U28: 85 | V28: 85 | W28: =IF(ABS(S28) < 0.01,"TAK","NIE") -> TAK
B29: 27 | C29: 0.449387 | D29: 1.11088 | E29: -0.004401 | F29: 0.010629 | G29: 0.000105 | H29: 1 | I29: 52 | J29: =IF(ABS(G29) < 0.01,"TAK","NIE") -> TAK | K29: -1e-06 | L29: 0.001289 | M29: 2e-06 | N29: 1 | O29: 61 | P29: =IF(ABS(M29) < 0.01,"TAK","NIE") -> TAK | Q29: 0.004991 | R29: 0.017412 | S29: 0.00044 | T29: 1 | U29: 82 | V29: 82 | W29: =IF(ABS(S29) < 0.01,"TAK","NIE") -> TAK
B30: 28 | C30: 1.582503 | D30: 0.181093 | E30: 1.746668 | F30: -0.864739 | G30: 0.298717 | H30: 1 | I30: 48 | J30: =IF(ABS(G30) < 0.01,"TAK","NIE") -> NIE | K30: 1.747339 | L30: -0.872071 | M30: 0.298641 | N30: 1 | O30: 55 | P30: =IF(ABS(M30) < 0.01,"TAK","NIE") -> NIE | Q30: 1.745751 | R30: -0.855082 | S30: 0.298974 | T30: 1 | U30: 78 | V30: 78 | W30: =IF(ABS(S30) < 0.01,"TAK","NIE") -> NIE
B31: 29 | C31: 0.825288 | D31: 1.830612 | E31: -0.004111 | F31: 0.009926 | G31: 9.2e-05 | H31: 1 | I31: 58 | J31: =IF(ABS(G31) < 0.01,"TAK","NIE") -> TAK | K31: -3.2e-05 | L31: 0.001333 | M31: 2e-06 | N31: 1 | O31: 64 | P31: =IF(ABS(M31) < 0.01,"TAK","NIE") -> TAK | Q31: 1.068885 | R31: -0.516375 | S31: 0.877682 | T31: 1 | U31: 94 | V31: 94 | W31: =IF(ABS(S31) < 0.01,"TAK","NIE") -> NIE
B32: 30 | C32: 1.14556 | D32: 1.142695 | E32: -0.000868 | F32: 0.008367 | G32: 6.4e-05 | H32: 1 | I32: 30 | J32: =IF(ABS(G32) < 0.01,"TAK","NIE") -> TAK | K32: 0.0006 | L32: 1.6e-05 | M32: 1e-06 | N32: 1 | O32: 73 | P32: =IF(ABS(M32) < 0.01,"TAK","NIE") -> TAK | Q32: 1.071373 | R32: -0.516891 | S32: 0.877713 | T32: 1 | U32: 88 | V32: 88 | W32: =IF(ABS(S32) < 0.01,"TAK","NIE") -> NIE
B33: 31 | C33: 0.492431 | D33: 0.176679 | E33: 0.004691 | F33: -0.006127 | G33: 5.3e-05 | H33: 1 | I33: 23 | J33: =IF(ABS(G33) < 0.01,"TAK","NIE") -> TAK | K33: -0.000101 | L33: -0.001212 | M33: 2e-06 | N33: 1 | O33: 46 | P33: =IF(ABS(M33) < 0.01,"TAK","NIE") -> TAK | Q33: 0.014848 | R33: 0.011085 | S33: 0.000728 | T33: 1 | U33: 61 | V33: 61 | W33: =IF(ABS(S33) < 0.01,"TAK","NIE") -> TAK
B34: 32 | C34: 0.169951 | D34: 0.95218 | E34: -0.004259 | F34: 0.010284 | G34: 9.8e-05 | H34: 1 | I34: 52 | J34: =IF(ABS(G34) < 0.01,"TAK","NIE") -> TAK | K34: -8.6e-05 | L34: 0.001652 | M34: 3e-06 | N34: 1 | O34: 58 | P34: =IF(ABS(M34) < 0.01,"TAK","NIE") -> TAK | Q34: 0.003152 | R34: 0.018402 | S34: 0.000417 | T34: 1 | U34: 77 | V34: 77 | W34: =IF(ABS(S34) < 0.01,"TAK","NIE") -> TAK
B35: 33 | C35: 0.025183 | D35: 0.522077 | E35: -0.004399 | F35: 0.010627 | G35: 0.000105 | H35: 1 | I35: 45 | J35: =IF(ABS(G35) < 0.01,"TAK","NIE") -> TAK | K35: -0.000161 | L35: 0.001391 | M35: 2e-06 | N35: 1 | O35: 55 | P35: =IF(ABS(M35) < 0.01,"TAK","NIE") -> TAK | Q35: 0.000897 | R35: 0.018611 | S35: 0.000365 | T35: 1 | U35: 65 | V35: 65 | W35: =IF(ABS(S35) < 0.01,"TAK","NIE") -> TAK
B36: 34 | C36: 0.214584 | D36: 0.825378 | E36: -0.004186 | F36: 0.010109 | G36: 9.5e-05 | H36: 1 | I36: 50 | J36: =IF(ABS(G36) < 0.01,"TAK","NIE") -> TAK | K36: -1.4e-05 | L36: 0.001445 | M36: 2e-06 | N36: 1 | O36: 58 | P36: =IF(ABS(M36) < 0.01,"TAK","NIE") -> TAK | Q36: 0.004309 | R36: 0.017752 | S36: 0.000429 | T36: 1 | U36: 75 | V36: 75 | W36: =IF(ABS(S36) < 0.01,"TAK","NIE") -> TAK
B37: 35 | C37: 1.240483 | D37: 1.142715 | E37: 0.004389 | F37: -0.010083 | G37: 9.6e-05 | H37: 1 | I37: 43 | J37: =IF(ABS(G37) < 0.01,"TAK","NIE") -> TAK | K37: nan | L37: inf | M37: nan | N37: 1 | O37: 73 | P37: =IF(ABS(M37) < 0.01,"TAK","NIE") -> #VALUE! | Q37: 1.072387 | R37: -0.516877 | S37: 0.877727 | T37: 1 | U37: 88 | V37: 88 | W37: =IF(ABS(S37) < 0.01,"TAK","NIE") -> NIE
B38: 36 | C38: 1.223436 | D38: 0.453098 | E38: 0.004383 | F38: -0.010568 | G38: 0.000104 | H38: 1 | I38: 71 | J38: =IF(ABS(G38) < 0.01,"TAK","NIE") -> TAK | K38: nan | L38: nan | M38: nan | N38: 1 | O38: 46 | P38: =IF(ABS(M38) < 0.01,"TAK","NIE") -> #VALUE! | Q38: 1.073332 | R38: -0.51718 | S38: 0.877724 | T38: 1 | U38: 78 | V38: 78 | W38: =IF(ABS(S38) < 0.01,"TAK","NIE") -> NIE
B39: 37 | C39: 0.771659 | D39: 0.660272 | E39: -0.00407 | F39: 0.010267 | G39: 9.7e-05 | H39: 1 | I39: 36 | J39: =IF(ABS(G39) < 0.01,"TAK","NIE") -> TAK | K39: -0.000915 | L39: 0.000709 | M39: 2e-06 | N39: 1 | O39: 49 | P39: =IF(ABS(M39) < 0.01,"TAK","NIE") -> TAK | Q39: 1.066858 | R39: -0.517016 | S39: 0.877601 | T39: 1 | U39: 81 | V39: 81 | W39: =IF(ABS(S39) < 0.01,"TAK","NIE") -> NIE
B40: 38 | C40: 0.147155 | D40: 1.677727 | E40: -0.004431 | F40: 0.010697 | G40: 0.000106 | H40: 1 | I40: 59 | J40: =IF(ABS(G40) < 0.01,"TAK","NIE") -> TAK | K40: -0.00016 | L40: 0.00181 | M40: 3e-06 | N40: 1 | O40: 61 | P40: =IF(ABS(M40) < 0.01,"TAK","NIE") -> TAK | Q40: 0.001567 | R40: 0.018405 | S40: 0.000372 | T40: 1 | U40: 88 | V40: 88 | W40: =IF(ABS(S40) < 0.01,"TAK","NIE") -> TAK
...

Sheet Tabela 2
A1: Długość kroku | B1: Metoda najszybszego spadku | H1: Metoda gradientów sprzężonych | N1: Metoda Newtona
B2: x1* | C2: x2* | D2: y* | E2: f_calls | F2: g_calls | G2: Liczba minimów globalnych | H2: x1* | I2: x2* | J2: y* | K2: f_calls | L2: g_calls | M2: Liczba minimów globalnych | N2: x1* | O2: x2* | P2: y* | Q2: f_calls | R2: g_calls | S2: H_calls | T2: Liczba minimów globalnych
A3: 0.05 | B3: ='Tabela 1'!E103 -> -0.0022352941 | C3: ='Tabela 1'!F103 -> 0.0062816765 | D3: ='Tabela 1'!G103 -> 9.2176471e-05 | E3: ='Tabela 1'!H103 -> 1 | F3: ='Tabela 1'!I103 -> 46.455882 | G3: ='Tabela 1'!J103 -> 68 | H3: ='Tabela 1'!K103 -> -0.00018059677 | I3: ='Tabela 1'!L103 -> 0.0008461129 | ... T3: ='Tabela 1'!W103 -> 34
A4: 0.25 | B4: ='Tabela 1'!E204 -> -9.7215909e-05 | C4: ='Tabela 1'!F204 -> 0.00023482955 | D4: ='Tabela 1'!G204 -> 1.2159091e-06 | E4: ='Tabela 1'!H204 -> 1 | F4: ='Tabela 1'!I204 -> 12.863636 | G4: ='Tabela 1'!J204 -> 88 | H4: ='Tabela 1'!K204 -> -7.6486486e-06 | I4: ='Tabela 1'!L204 -> 8.9513514e-05 | ... T4: ='Tabela 1'!W204 -> 23
A5: M. zk. | B5: ='Tabela 1'!E305 -> -0.00031662903 | C5: ='Tabela 1'!F305 -> 0.00085472581 | D5: ='Tabela 1'!G305 -> 1.85e-05 | E5: ='Tabela 1'!H305 -> 395.83871 | F5: ='Tabela 1'!I305 -> 26.322581 | G5: ='Tabela 1'!J305 -> 62 | H5: ='Tabela 1'!K305 -> -4.7527273e-05 | I5: ='Tabela 1'!L305 -> 0.00036803636 | ... T5: ='Tabela 1'!W305 -> 24

Sheet Wykresy
A1: Nr iteracji | B1: Metoda najszybszego spadku | H1: Metoda gradientów sprzężonych | N1: Metoda Newtona
B2: 0.05 | D2: 0.25 | F2: M. zk. | H2: 0.05 | J2: 0.25 | L2: M. zk. | N2: 0.05 | P2: 0.25 | R2: M. zk.
B3: x1* | C3: x2* | D3: x1* | E3: x2* | F3: x1* | G3: x2* | H3: x1* | I3: x2* | J3: x1* | K3: x2* | L3: x1* | M3: x2* | N3: x1* | O3: x2* | P3: x1* | Q3: x2* | R3: x1* | S3: x2*
A4: 0 | B4: 2 | C4: 2 | D4: 2 | E4: 2 | F4: 2 | G4: 2 | H4: 2 | I4: 2 | J4: 2 | K4: 2 | L4: 2 | M4: 2 | N4: 2 | O4: 2 | P4: 2 | Q4: 2 | R4: 2 | S4: 2
A5: 1 | B5: 1.58 | C5: 1.7 | D5: -0.1 | E5: 0.5 | F5: 1.163415 | G5: 1.402439 | H5: 1.58 | I5: 1.7 | J5: -0.1 | K5: 0.5 | L5: 1.163415 | M5: 1.402439 | N5: 1.991843 | O5: 1.854079 | P5: 1.959215 | Q5: 1.270393 | R5: 1.983752 | S5: 1.709344
A6: 2 | B6: 1.514976 | C6: 1.451 | D6: -0.126047 | E6: 0.275 | F6: 1.006684 | G6: 1.007223 | H6: 1.410561 | I6: 1.376418 | J6: -0.142224 | K6: 0.263445 | L6: 0.977321 | M6: 0.98625 | N6: 1.983875 | O6: 1.715563 | P6: 1.923295 | Q6: 0.725852 | R6: 1.968259 | S6: 1.448066
A7: 3 | B7: 1.470599 | C7: 1.230151 | D7: -0.070845 | E7: 0.169012 | F7: 0.829104 | G7: 0.706338 | H7: 1.254681 | I7: 0.948405 | J7: -0.080908 | K7: 0.099825 | L7: 0.529651 | M7: 0.10701 | N7: 1.976094 | O7: 1.584078 | P7: 1.892003 | Q7: 0.319624 | R7: 1.953507 | S7: 1.213212
A8: 4 | B8: 1.43895 | C8: 1.033606 | D8: -0.042626 | E8: 0.102217 | F8: 0.627846 | G8: 0.483072 | H8: 1.124342 | I8: 0.540146 | J8: -0.008956 | K8: 0.025961 | L8: 0.019008 | M8: -0.648548 | N8: 1.968498 | O8: 1.45927 | P8: 1.865066 | Q8: 0.016686 | R8: 1.939481 | S8: 1.002118
A9: 5 | B9: 1.416706 | C9: 0.858298 | D9: -0.025636 | E9: 0.061765 | F9: 0.423425 | G9: 0.324321 | H9: 1.011767 | I9: 0.212722 | J9: -0.004279 | K9: 0.012948 | L9: 0.014039 | M9: -0.612982 | N9: 1.961086 | O9: 1.3408 | P9: 1.842176 | Q9: -0.209174 | R9: 1.926167 | S9: 0.812391
A10: … | B10: 1.402221 | C10: 0.701633 | D10: -0.015459 | E10: 0.037291 | F10: 0.252842 | G10: 0.21755 | H10: 0.902916 | I10: -0.03467 | J10: -0.002071 | K10: 0.004298 | L10: 0.064796 | M10: -0.458641 | N10: 1.953856 | O10: 1.228348 | P10: 1.822988 | Q10: -0.377558 | R10: 1.913548 | S10: 0.641875
B11: 1.39463 | C11: 0.561359 | D11: -0.009327 | E11: 0.02251 | F11: 0.137108 | G11: 0.149035 | H11: 0.780828 | I11: -0.230475 | J11: -0.000808 | K11: 0.001623 | L11: 0.091361 | M11: -0.353709 | N11: 1.946805 | O11: 1.121609 | P11: 1.807125 | Q11: -0.503111 | R11: 1.901608 | S11: 0.48863
B12: 1.393477 | C12: 0.435491 | D12: -0.005628 | E12: 0.013587 | F12: 0.068718 | G12: 0.105694 | H12: 0.623663 | I12: -0.403618 | J12: -0.000222 | K12: 0.000623 | L12: 0.090559 | M12: -0.292163 | N12: 1.939933 | O12: 1.020295 | P12: 1.794189 | Q12: -0.596756 | R12: 1.89033 | S12: 0.350911
B13: 1.398524 | C13: 0.322268 | D13: -0.003397 | E13: 0.008201 | F13: 0.030952 | G13: 0.077797 | H13: 0.419534 | I13: -0.555061 | N13: 1.933237 | O13: 0.92413 | P13: 1.783778 | Q13: -0.666635 | R13: 1.879696 | S13: 0.227147
B14: 1.409628 | C14: 0.220115 | D14: -0.00205 | E14: 0.00495 | F14: 0.010886 | G14: 0.059219 | H14: 0.208577 | I14: -0.646403 | N14: 1.926715 | O14: 0.832853 | P14: 1.7755 | Q14: -0.718809 | R14: 1.869687 | S14: 0.115927
B15: 1.426621 | C15: 0.127622 | D15: -0.001237 | E15: 0.002987 | F15: 0.000652 | G15: 0.046339 | H15: -0.016991 | I15: -0.686608 | N15: 1.920366 | O15: 0.746217 | P15: 1.768989 | Q15: -0.757789 | R15: 1.860282 | S15: 0.015979
B16: 1.449186 | C16: 0.043529 | D16: -0.000747 | E16: 0.001803 | F16: -0.004223 | G16: 0.037044 | H16: -0.450323 | I16: -0.70106 | N16: 1.914186 | O16: 0.663987 | P16: 1.763916 | Q16: -0.786929 | R16: 1.851463 | S16: -0.073839
B17: 1.476718 | C17: -0.033283 | D17: -0.000451 | E17: 0.001088 | F17: -0.00623 | G17: 0.030086 | H17: -1.728939 | I17: -0.654643 | N17: 1.908174 | O17: 0.585939 | P17: 1.759995 | Q17: -0.808726 | R17: 1.843208 | S17: -0.154554
B18: 1.508174 | C18: -0.103791 | F18: -0.006745 | G18: 0.024714 | H18: -3.414193 | I18: -0.43917 | N18: 1.902328 | O18: 0.511861 | P18: 1.756984 | Q18: -0.825038 | R18: 1.835495 | S18: -0.227091
B19: 1.541983 | C19: -0.16882 | F19: -0.006519 | G19: 0.020463 | N19: 1.896646 | O19: 0.441551 | P19: 1.754684 | Q19: -0.837252 | R19: 1.828303 | S19: -0.29228
B20: 1.576088 | C20: -0.229037 | F20: -0.00596 | G20: 0.017036 | N20: 1.891125 | O20: 0.374818 | P20: 1.752934 | Q20: -0.846399 | R20: 1.821607 | S20: -0.350866
B21: 1.608226 | C21: -0.284938 | F21: -0.005283 | G21: 0.014236 | N21: 1.885763 | O21: 0.311479 | P21: 1.751608 | Q21: -0.853253 | R21: 1.815386 | S21: -0.403522
B22: 1.636418 | C22: -0.336856 | F22: -0.004596 | G22: 0.011927 | N22: 1.880558 | O22: 0.251364 | P22: 1.750605 | Q22: -0.858389 | R22: 1.809617 | S22: -0.450849
B23: 1.659485 | C23: -0.384991 | F23: -0.003953 | G23: 0.010009 | N23: 1.875507 | O23: 0.194307 | P23: 1.749848 | Q23: -0.862239 | R23: 1.804276 | S23: -0.49339
B24: 1.677277 | C24: -0.429466 | F24: -0.003375 | G24: 0.008409 | N24: 1.870608 | O24: 0.140154 | P24: 1.749278 | Q24: -0.865125 | R24: 1.79934 | S24: -0.531631
B25: 1.69047 | C25: -0.470383 | F25: -0.002868 | G25: 0.00707 | N25: 1.865858 | O25: 0.088756 | P25: 1.748848 | Q25: -0.867289 | R25: 1.794785 | S25: -0.566008
B26: 1.700119 | C26: -0.507869 | F26: -0.00243 | G26: 0.005947 | N26: 1.861256 | O26: 0.039973 | P26: 1.748525 | Q26: -0.868911 | R26: 1.79059 | S26: -0.596914
B27: 1.707258 | C27: -0.542088 | F27: -0.002054 | G27: 0.005005 | N27: 1.856797 | O27: -0.006328 | P27: 1.748283 | Q27: -0.870128 | R27: 1.786732 | S27: -0.624702
B28: 1.712699 | C28: -0.573242 | F28: -0.001734 | G28: 0.004212 | N28: 1.852481 | O28: -0.050273 | P28: 1.748101 | Q28: -0.87104 | R28: 1.78319 | S28: -0.649688
B29: 1.717002 | C29: -0.601553 | N29: 1.848303 | O29: -0.091983 | R29: 1.779941 | S29: -0.672156
B30: 1.720529 | C30: -0.627247 | N30: 1.844262 | O30: -0.131571 | R30: 1.776966 | S30: -0.692361
B31: 1.723505 | C31: -0.650549 | N31: 1.840355 | O31: -0.169145 | R31: 1.774246 | S31: -0.710534
B32: 1.726068 | C32: -0.671669 | N32: 1.836578 | O32: -0.204809 | R32: 1.771761 | S32: -0.726878
B33: 1.728307 | C33: -0.690806 | N33: 1.83293 | O33: -0.238659 | R33: 1.769494 | S33: -0.741581
B34: 1.730282 | C34: -0.708141 | N34: 1.829408 | O34: -0.270788 | R34: 1.767428 | S34: -0.754806
B35: 1.732034 | C35: -0.723841 | N35: 1.826008 | O35: -0.301283 | R35: 1.765548 | S35: -0.766704
B36: 1.733594 | C36: -0.738058 | N36: 1.822727 | O36: -0.330229 | R36: 1.763837 | S36: -0.777408
B37: 1.734988 | C37: -0.750932 | N37: 1.819564 | O37: -0.357704 | R37: 1.762282 | S37: -0.787039
B38: 1.736236 | C38: -0.762588 | N38: 1.816515 | O38: -0.383783 | R38: 1.76087 | S38: -0.795705
B39: 1.737354 | C39: -0.773141 | N39: 1.813577 | O39: -0.408538 | R39: 1.759589 | S39: -0.803503
B40: 1.738358 | C40: -0.782695 | N40: 1.810747 | O40: -0.432036 | R40: 1.758427 | S40: -0.810521
...

Sheet Klasyfikator
A1: Długość kroku | B1: Metoda gradientów sprzężonych
B2: θ0* | C2: θ1* | D2: θ2* | E2: J(θ*) | F2: P(θ*) | G2: g_calls
A3: 0.01
A4: 0.001 | B4: -0.000212 | C4: 0.006289 | D4: 0.01098 | E4: 0.534456 | F4: 0.7 | G4: 10
A5: 0.0001 | B5: 7.5e-05 | C5: 0.0082 | D5: 0.009534 | E5: 0.535123 | F5: 0.7 | G5: 16

Sheet Wykres
D4: 7.5e-05 | E4: 0.0082 | F4: 0.009534
K9: 80
F13: 1 | H13: 0 | J13: x1 | K13: x2
B14: 1 | C14: 57 | D14: 68 | E14: 1 | F14: {=IF(E14,C14:D14, NA())} -> 57 | G14: 68 | H14: {=IF(E14=0,C14:D14,NA())} -> #N/A | J14: 57 | K14: =-($D$4+$E$4*C14)/$F$4+$K$9 -> 30.96759
B15: 1 | C15: 86 | D15: 87 | E15: 1 | F15: {=IF(E15,C15:D15, NA())} -> 86 | G15: 87 | H15: {=IF(E15=0,C15:D15,NA())} -> #N/A | J15: 86 | K15: =-($D$4+$E$4*C15)/$F$4+$K$9 -> 6.025278
B16: 1 | C16: 86 | D16: 46 | E16: 1 | F16: {=IF(E16,C16:D16, NA())} -> 86 | G16: 46 | H16: {=IF(E16=0,C16:D16,NA())} -> #N/A | J16: 86 | K16: =-($D$4+$E$4*C16)/$F$4+$K$9 -> 6.025278
B17: 1 | C17: 71 | D17: 25 | E17: 0 | F17: {=IF(E17,C17:D17, NA())} -> #N/A | H17: {=IF(E17=0,C17:D17,NA())} -> 71 | I17: 25 | J17: 71 | K17: =-($D$4+$E$4*C17)/$F$4+$K$9 -> 18.926474
B18: 1 | C18: 75 | D18: 77 | E18: 1 | F18: {=IF(E18,C18:D18, NA())} -> 75 | G18: 77 | H18: {=IF(E18=0,C18:D18,NA())} -> #N/A | J18: 75 | K18: =-($D$4+$E$4*C18)/$F$4+$K$9 -> 15.486155
B19: 1 | C19: 84 | D19: 53 | E19: 1 | F19: {=IF(E19,C19:D19, NA())} -> 84 | G19: 53 | H19: {=IF(E19=0,C19:D19,NA())} -> #N/A | J19: 84 | K19: =-($D$4+$E$4*C19)/$F$4+$K$9 -> 7.7454374
B20: 1 | C20: 89 | D20: 93 | E20: 1 | F20: {=IF(E20,C20:D20, NA())} -> 89 | G20: 93 | H20: {=IF(E20=0,C20:D20,NA())} -> #N/A | J20: 89 | K20: =-($D$4+$E$4*C20)/$F$4+$K$9 -> 3.4450388
B21: 1 | C21: 68 | D21: 96 | E21: 1 | F21: {=IF(E21,C21:D21, NA())} -> 68 | G21: 96 | H21: {=IF(E21=0,C21:D21,NA())} -> #N/A | J21: 68 | K21: =-($D$4+$E$4*C21)/$F$4+$K$9 -> 21.506713
B22: 1 | C22: 50 | D22: 34 | E22: 0 | F22: {=IF(E22,C22:D22, NA())} -> #N/A | H22: {=IF(E22=0,C22:D22,NA())} -> 50 | I22: 34 | J22: 50 | K22: =-($D$4+$E$4*C22)/$F$4+$K$9 -> 36.988148
B23: 1 | C23: 90 | D23: 92 | E23: 1 | F23: {=IF(E23,C23:D23, NA())} -> 90 | G23: 92 | H23: {=IF(E23=0,C23:D23,NA())} -> #N/A | J23: 90 | K23: =-($D$4+$E$4*C23)/$F$4+$K$9 -> 2.5849591
B24: 1 | C24: 53 | D24: 87 | E24: 1 | F24: {=IF(E24,C24:D24, NA())} -> 53 | G24: 87 | H24: {=IF(E24=0,C24:D24,NA())} -> #N/A | J24: 53 | K24: =-($D$4+$E$4*C24)/$F$4+$K$9 -> 34.407909
B25: 1 | C25: 40 | D25: 49 | E25: 0 | F25: {=IF(E25,C25:D25, NA())} -> #N/A | H25: {=IF(E25=0,C25:D25,NA())} -> 40 | I25: 49 | J25: 40 | K25: =-($D$4+$E$4*C25)/$F$4+$K$9 -> 45.588945
B26: 1 | C26: 40 | D26: 68 | E26: 1 | F26: {=IF(E26,C26:D26, NA())} -> 40 | G26: 68 | H26: {=IF(E26=0,C26:D26,NA())} -> #N/A | J26: 40 | K26: =-($D$4+$E$4*C26)/$F$4+$K$9 -> 45.588945
B27: 1 | C27: 28 | D27: 56 | E27: 0 | F27: {=IF(E27,C27:D27, NA())} -> #N/A | H27: {=IF(E27=0,C27:D27,NA())} -> 28 | I27: 56 | J27: 28 | K27: =-($D$4+$E$4*C27)/$F$4+$K$9 -> 55.909901
B28: 1 | C28: 97 | D28: 88 | E28: 1 | F28: {=IF(E28,C28:D28, NA())} -> 97 | G28: 88 | H28: {=IF(E28=0,C28:D28,NA())} -> #N/A | J28: 97 | K28: =-($D$4+$E$4*C28)/$F$4+$K$9 -> -3.4355989
B29: 1 | C29: 35 | D29: 35 | E29: 0 | F29: {=IF(E29,C29:D29, NA())} -> #N/A | H29: {=IF(E29=0,C29:D29,NA())} -> 35 | I29: 35 | J29: 35 | K29: =-($D$4+$E$4*C29)/$F$4+$K$9 -> 49.889343
B30: 1 | C30: 59 | D30: 80 | E30: 1 | F30: {=IF(E30,C30:D30, NA())} -> 59 | G30: 80 | H30: {=IF(E30=0,C30:D30,NA())} -> #N/A | J30: 59 | K30: =-($D$4+$E$4*C30)/$F$4+$K$9 -> 29.24743
B31: 1 | C31: 29 | D31: 75 | E31: 0 | F31: {=IF(E31,C31:D31, NA())} -> #N/A | H31: {=IF(E31=0,C31:D31,NA())} -> 29 | I31: 75 | J31: 29 | K31: =-($D$4+$E$4*C31)/$F$4+$K$9 -> 55.049822
B32: 1 | C32: 44 | D32: 30 | E32: 0 | F32: {=IF(E32,C32:D32, NA())} -> #N/A | H32: {=IF(E32=0,C32:D32,NA())} -> 44 | I32: 30 | J32: 44 | K32: =-($D$4+$E$4*C32)/$F$4+$K$9 -> 42.148626
B33: 1 | C33: 54 | D33: 73 | E33: 1 | F33: {=IF(E33,C33:D33, NA())} -> 54 | G33: 73 | H33: {=IF(E33=0,C33:D33,NA())} -> #N/A | J33: 54 | K33: =-($D$4+$E$4*C33)/$F$4+$K$9 -> 33.547829
B34: 1 | C34: 22 | D34: 77 | E34: 0 | F34: {=IF(E34,C34:D34, NA())} -> #N/A | H34: {=IF(E34=0,C34:D34,NA())} -> 22 | I34: 77 | J34: 22 | K34: =-($D$4+$E$4*C34)/$F$4+$K$9 -> 61.07038
B35: 1 | C35: 53 | D35: 48 | E35: 1 | F35: {=IF(E35,C35:D35, NA())} -> 53 | G35: 48 | H35: {=IF(E35=0,C35:D35,NA())} -> #N/A | J35: 53 | K35: =-($D$4+$E$4*C35)/$F$4+$K$9 -> 34.407909
B36: 1 | C36: 66 | D36: 42 | E36: 1 | F36: {=IF(E36,C36:D36, NA())} -> 66 | G36: 42 | H36: {=IF(E36=0,C36:D36,NA())} -> #N/A | J36: 66 | K36: =-($D$4+$E$4*C36)/$F$4+$K$9 -> 23.226872
B37: 1 | C37: 26 | D37: 87 | E37: 0 | F37: {=IF(E37,C37:D37, NA())} -> #N/A | H37: {=IF(E37=0,C37:D37,NA())} -> 26 | I37: 87 | J37: 26 | K37: =-($D$4+$E$4*C37)/$F$4+$K$9 -> 57.630061
B38: 1 | C38: 43 | D38: 67 | E38: 1 | F38: {=IF(E38,C38:D38, NA())} -> 43 | G38: 67 | H38: {=IF(E38=0,C38:D38,NA())} -> #N/A | J38: 43 | K38: =-($D$4+$E$4*C38)/$F$4+$K$9 -> 43.008706
B39: 1 | C39: 70 | D39: 62 | E39: 1 | F39: {=IF(E39,C39:D39, NA())} -> 70 | G39: 62 | H39: {=IF(E39=0,C39:D39,NA())} -> #N/A | J39: 70 | K39: =-($D$4+$E$4*C39)/$F$4+$K$9 -> 19.786553
B40: 1 | C40: 100 | D40: 96 | E40: 1 | F40: {=IF(E40,C40:D40, NA())} -> 100 | G40: 96 | H40: {=IF(E40=0,C40:D40,NA())} -> #N/A | J40: 100 | K40: =-($D$4+$E$4*C40)/$F$4+$K$9 -> -6.0158381
B41: 1 | C41: 64 | D41: 56 | E41: 1 | F41: {=IF(E41,C41:D41, NA())} -> 64 | G41: 56 | H41: {=IF(E41=0,C41:D41,NA())} -> #N/A | J41: 64 | K41: =-($D$4+$E$4*C41)/$F$4+$K$9 -> 24.947032
B42: 1 | C42: 79 | D42: 82 | E42: 1 | F42: {=IF(E42,C42:D42, NA())} -> 79 | G42: 82 | H42: {=IF(E42=0,C42:D42,NA())} -> #N/A | J42: 79 | K42: =-($D$4+$E$4*C42)/$F$4+$K$9 -> 12.045836
B43: 1 | C43: 48 | D43: 91 | E43: 1 | F43: {=IF(E43,C43:D43, NA())} -> 48 | G43: 91 | H43: {=IF(E43=0,C43:D43,NA())} -> #N/A | J43: 48 | K43: =-($D$4+$E$4*C43)/$F$4+$K$9 -> 38.708307
B44: 1 | C44: 82 | D44: 79 | E44: 1 | F44: {=IF(E44,C44:D44, NA())} -> 82 | G44: 79 | H44: {=IF(E44=0,C44:D44,NA())} -> #N/A | J44: 82 | K44: =-($D$4+$E$4*C44)/$F$4+$K$9 -> 9.4655968
B45: 1 | C45: 44 | D45: 52 | E45: 1 | F45: {=IF(E45,C45:D45, NA())} -> 44 | G45: 52 | H45: {=IF(E45=0,C45:D45,NA())} -> #N/A | J45: 44 | K45: =-($D$4+$E$4*C45)/$F$4+$K$9 -> 42.148626
B46: 1 | C46: 50 | D46: 45 | E46: 1 | F46: {=IF(E46,C46:D46, NA())} -> 50 | G46: 45 | H46: {=IF(E46=0,C46:D46,NA())} -> #N/A | J46: 50 | K46: =-($D$4+$E$4*C46)/$F$4+$K$9 -> 36.988148
B47: 1 | C47: 95 | D47: 53 | E47: 1 | F47: {=IF(E47,C47:D47, NA())} -> 95 | G47: 53 | H47: {=IF(E47=0,C47:D47,NA())} -> #N/A | J47: 95 | K47: =-($D$4+$E$4*C47)/$F$4+$K$9 -> -1.7154395
B48: 1 | C48: 28 | D48: 45 | E48: 0 | F48: {=IF(E48,C48:D48, NA())} -> #N/A | H48: {=IF(E48=0,C48:D48,NA())} -> 28 | I48: 45 | J48: 28 | K48: =-($D$4+$E$4*C48)/$F$4+$K$9 -> 55.909901
B49: 1 | C49: 37 | D49: 38 | E49: 0 | F49: {=IF(E49,C49:D49, NA())} -> #N/A | H49: {=IF(E49=0,C49:D49,NA())} -> 37 | I49: 38 | J49: 37 | K49: =-($D$4+$E$4*C49)/$F$4+$K$9 -> 48.169184
B50: 1 | C50: 71 | D50: 81 | E50: 1 | F50: {=IF(E50,C50:D50, NA())} -> 71 | G50: 81 | H50: {=IF(E50=0,C50:D50,NA())} -> #N/A | J50: 71 | K50: =-($D$4+$E$4*C50)/$F$4+$K$9 -> 18.926474
...
