Workbook

Sheet Tabela 1
A1: Długość kroku | B1: Lp. | C1: x1(0) | D1: x2(0) | E1: Metoda Hooke’a-Jeevesa | J1: Metoda Rosenbrocka
E2: x1* | F2: x2* | G2: y* | H2: Liczba wywołań funkcji celu | I2: Minimum globalne [TAK/NIE] | J2: x1* | K2: x2* | L2: y* | M2: Liczba wywołań funkcji celu | N2: Minimum globalne [TAK/NIE]
A3: 0.1 | B3: 1 | C3: 0.134677 | D3: -0.372999 | E3: 0.004677 | F3: -0.002999 | G3: 0.000983 | H3: 49 | I3: =IF(G3<$Q$4,"tak","nie") -> tak | J3: 0.041715 | K3: 0.011829 | L3: 0.059386 | M3: 24 | N3: =IF(L3<$Q$4,"tak","nie") -> nie | Q3: ponieżej minimuym globalne
B4: 2 | C4: 0.881826 | D4: 0.909265 | E4: 0.781826 | F4: 0.779265 | G4: 1.241907 | H4: 38 | I4: =IF(G4<$Q$4,"tak","nie") -> nie | J4: 0.793944 | K4: 0.815726 | L4: 1.304505 | M4: 16 | N4: =IF(L4<$Q$4,"tak","nie") -> nie | Q4: =MIN(G3:G102)+0.01 -> 0.010128
B5: 3 | C5: -0.816928 | D5: -0.967633 | E5: -0.786928 | F5: -0.767633 | G5: 1.24592 | H5: 40 | I5: =IF(G5<$Q$4,"tak","nie") -> nie | J5: -0.793313 | K5: -0.77801 | L5: 1.250901 | M5: 16 | N5: =IF(L5<$Q$4,"tak","nie") -> nie
B6: 4 | C6: -0.541105 | D6: -0.506715 | E6: -0.771105 | F6: -0.776715 | G6: 1.240206 | H6: 47 | I6: =IF(G6<$Q$4,"tak","nie") -> nie | J6: -0.789218 | K6: -0.766707 | L6: 1.24828 | M6: 18 | N6: =IF(L6<$Q$4,"tak","nie") -> nie
B7: 5 | C7: 0.420193 | D7: 0.889162 | E7: 0.760193 | F7: 0.789162 | G7: 1.252767 | H7: 54 | I7: =IF(G7<$Q$4,"tak","nie") -> nie | J7: 0.751193 | K7: 0.822962 | L7: 1.330351 | M7: 14 | N7: =IF(L7<$Q$4,"tak","nie") -> nie
B8: 6 | C8: -0.07677 | D8: 0.805247 | E8: -0.00677 | F8: 0.775247 | G8: 0.621305 | H8: 37 | I8: =IF(G8<$Q$4,"tak","nie") -> nie | J8: 0.002834 | K8: 0.785247 | L8: 0.623574 | M8: 16 | N8: =IF(L8<$Q$4,"tak","nie") -> nie
B9: 7 | C9: -0.680256 | D9: 0.231745 | E9: -0.780256 | F9: 0.001745 | G9: 0.620895 | H9: 43 | I9: =IF(G9<$Q$4,"tak","nie") -> nie | J9: -0.778037 | K9: -0.007458 | L9: 0.621953 | M9: 16 | N9: =IF(L9<$Q$4,"tak","nie") -> nie
B10: 8 | C10: -0.070129 | D10: -0.967765 | E10: -0.000129 | F10: -0.767765 | G10: 0.621341 | H10: 40 | I10: =IF(G10<$Q$4,"tak","nie") -> nie | J10: 0.000908 | K10: -0.776513 | L10: 0.619964 | M10: 14 | N10: =IF(L10<$Q$4,"tak","nie") -> nie
B11: 9 | C11: 0.647252 | D11: 0.272797 | E11: 0.777252 | F11: 0.002797 | G11: 0.620288 | H11: 45 | I11: =IF(G11<$Q$4,"tak","nie") -> nie | J11: 0.782553 | K11: 0.031578 | L11: 0.653359 | M11: 16 | N11: =IF(L11<$Q$4,"tak","nie") -> nie
B12: 10 | C12: -0.728708 | D12: 0.654181 | E12: -0.788708 | F12: 0.784181 | G12: 1.248639 | H12: 41 | I12: =IF(G12<$Q$4,"tak","nie") -> nie | J12: -0.773105 | K12: 0.774181 | L12: 1.239764 | M12: 22 | N12: =IF(L12<$Q$4,"tak","nie") -> nie
B13: 11 | C13: 0.384799 | D13: 0.121028 | E13: 0.784799 | F13: -0.008972 | G13: 0.62559 | H13: 49 | I13: =IF(G13<$Q$4,"tak","nie") -> nie | J13: 0.791499 | K13: 0.035609 | L13: 0.66882 | M13: 20 | N13: =IF(L13<$Q$4,"tak","nie") -> nie
B14: 12 | C14: 0.22287 | D14: 0.453486 | E14: -0.00713 | F14: 0.783486 | G14: 0.623868 | H14: 44 | I14: =IF(G14<$Q$4,"tak","nie") -> nie | J14: 0.015226 | K14: 0.769945 | L14: 0.62792 | M14: 22 | N14: =IF(L14<$Q$4,"tak","nie") -> nie
B15: 13 | C15: 0.620196 | D15: 0.667422 | E15: 0.760196 | F15: 0.767422 | G15: 1.247859 | H15: 45 | I15: =IF(G15<$Q$4,"tak","nie") -> nie | J15: 0.778856 | K15: 0.773442 | L15: 1.240261 | M15: 24 | N15: =IF(L15<$Q$4,"tak","nie") -> nie
B16: 14 | C16: 0.526252 | D16: 0.85686 | E16: 0.786252 | F16: 0.78686 | G16: 1.248485 | H16: 43 | I16: =IF(G16<$Q$4,"tak","nie") -> nie | J16: 0.736252 | K16: 0.81486 | L16: 1.335608 | M16: 12 | N16: =IF(L16<$Q$4,"tak","nie") -> nie
... B102: 100 | C102: 0.893714 | D102: -0.55807 | E102: 0.763714 | F102: -0.78807 | G102: 1.249035 | H102: 43 | I102: =IF(G102<$Q$4,"tak","nie") -> nie | J102: 0.780376 | K102: -0.781717 | L102: 1.242214 | M102: 16 | N102: =IF(L102<$Q$4,"tak","nie") -> nie
A103: 0.5 | B103: 1 | C103: 0.482224 | D103: 0.937398 | E103: 0.773724 | F103: 0.773898 | G103: 1.239726 | H103: 75 | I103: =IF(G103<$Q$4,"tak","nie") -> nie | J103: 0.775749 | K103: 0.774753 | L103: 1.239708 | M103: 34 | N103: =IF(L103<$Q$4,"tak","nie") -> nie
B104: 2 | C104: -0.498543 | D104: -0.863891 | E104: 0.001457 | F104: -0.772391 | G104: 0.620073 | H104: 74 | I104: =IF(G104<$Q$4,"tak","nie") -> nie | J104: -0.00039 | K104: -0.777712 | L104: 0.620123 | M104: 24 | N104: =IF(L104<$Q$4,"tak","nie") -> nie
B105: 3 | C105: 0.356242 | D105: 0.396904 | E105: 0.769242 | F105: 0.778404 | G105: 1.241033 | H105: 81 | I105: =IF(G105<$Q$4,"tak","nie") -> nie | J105: 0.76654 | K105: 0.778095 | L105: 1.24211 | M105: 36 | N105: =IF(L105<$Q$4,"tak","nie") -> nie
B106: 4 | C106: -0.060906 | D106: 0.438399 | E106: -0.002406 | F106: 0.774899 | G106: 0.620023 | H106: 73 | I106: =IF(G106<$Q$4,"tak","nie") -> nie | J106: 0.001094 | K106: 0.754297 | L106: 0.632736 | M106: 30 | N106: =IF(L106<$Q$4,"tak","nie") -> nie
B107: 5 | C107: 0.547087 | D107: 0.174639 | E107: 0.002087 | F107: 0.006639 | G107: 0.001542 | H107: 79 | I107: =IF(G107<$Q$4,"tak","nie") -> tak | J107: -0.007143 | K107: -0.00223 | L107: 0.001783 | M107: 38 | N107: =IF(L107<$Q$4,"tak","nie") -> tak
B108: 6 | C108: -0.335431 | D108: 0.341522 | E108: 0.001069 | F108: 0.769522 | G108: 0.620714 | H108: 79 | I108: =IF(G108<$Q$4,"tak","nie") -> nie | J108: 0.781835 | K108: 0.769246 | L108: 1.242195 | M108: 36 | N108: =IF(L108<$Q$4,"tak","nie") -> nie
B109: 7 | C109: -0.294793 | D109: 0.155909 | E109: 0.768207 | F109: 0.005909 | G109: 0.622267 | H109: 87 | I109: =IF(G109<$Q$4,"tak","nie") -> nie | J109: 0.766543 | K109: -0.001493 | L109: 0.621985 | M109: 24 | N109: =IF(L109<$Q$4,"tak","nie") -> nie
B110: 8 | C110: 0.809861 | D110: -0.129411 | E110: 0.778361 | F110: -0.006411 | G110: 0.621561 | H110: 67 | I110: =IF(G110<$Q$4,"tak","nie") -> nie | J110: 0.774416 | K110: -0.001548 | L110: 0.619916 | M110: 40 | N110: =IF(L110<$Q$4,"tak","nie") -> nie
B111: 9 | C111: 0.986058 | D111: -0.76512 | E111: 0.777558 | F111: -0.77862 | G111: 1.240404 | H111: 64 | I111: =IF(G111<$Q$4,"tak","nie") -> nie | J111: 0.776058 | K111: -0.76912 | L111: 1.240706 | M111: 16 | N111: =IF(L111<$Q$4,"tak","nie") -> nie
B112: 10 | C112: -0.948804 | D112: -0.885575 | E112: -0.780804 | F112: -0.780575 | G112: 1.241911 | H112: 66 | I112: =IF(G112<$Q$4,"tak","nie") -> nie | J112: -0.765192 | K112: -0.770043 | L112: 1.243173 | M112: 42 | N112: =IF(L112<$Q$4,"tak","nie") -> nie
B113: 11 | C113: -0.578899 | D113: 0.84494 | E113: -0.005399 | F113: 0.76844 | G113: 0.621991 | H113: 77 | I113: =IF(G113<$Q$4,"tak","nie") -> nie | J113: 0.000525 | K113: 0.771097 | L113: 0.620254 | M113: 28 | N113: =IF(L113<$Q$4,"tak","nie") -> nie
B114: 12 | C114: 0.396199 | D114: -0.39022 | E114: 0.777699 | F114: 0.00478 | G114: 0.620843 | H114: 72 | I114: =IF(G114<$Q$4,"tak","nie") -> nie | J114: 0.764253 | K114: -0.021034 | L114: 0.637294 | M114: 22 | N114: =IF(L114<$Q$4,"tak","nie") -> nie
B115: 13 | C115: 0.246166 | D115: 0.446462 | E115: 0.777666 | F115: 0.769462 | G115: 1.240806 | H115: 78 | I115: =IF(G115<$Q$4,"tak","nie") -> nie | J115: 0.780308 | K115: 0.770898 | L115: 1.241108 | M115: 24 | N115: =IF(L115<$Q$4,"tak","nie") -> nie
... B202: 100 | C202: -0.565321 | D202: 0.87414 | E202: 0.006679 | F202: 0.76914 | G202: 0.622226 | H202: 76 | I202: =IF(G202<$Q$4,"tak","nie") -> nie | J202: -0.003457 | K202: 0.76778 | L202: 0.621715 | M202: 22 | N202: =IF(L202<$Q$4,"tak","nie") -> nie
A203: 0.9 | B203: 1 | C203: -0.471311 | D203: 0.062016 | E203: 0.011989 | F203: 0.005316 | G203: 0.005473 | H203: 65 | I203: =IF(G203<$Q$4,"tak","nie") -> tak | J203: -0.840673 | K203: -0.020634 | L203: 0.770848 | M203: 24 | N203: =IF(L203<$Q$4,"tak","nie") -> nie
B204: 2 | C204: -0.034408 | D204: -0.677034 | E204: -0.010108 | F204: -0.782334 | G204: 0.624908 | H204: 51 | I204: =IF(G204<$Q$4,"tak","nie") -> nie | J204: 0.001592 | K204: -0.857034 | L204: 0.83325 | M204: 14 | N204: =IF(L204<$Q$4,"tak","nie") -> nie
B205: 3 | C205: -0.332893 | D205: -0.279821 | E205: 0.780407 | F205: 0.784879 | G205: 1.24393 | H205: 71 | I205: =IF(G205<$Q$4,"tak","nie") -> nie | J205: -0.023344 | K205: -0.026275 | L205: 0.039213 | M205: 30 | N205: =IF(L205<$Q$4,"tak","nie") -> nie
B206: 4 | C206: 0.141975 | D206: 0.628444 | E206: 0.009675 | F206: 0.785044 | G206: 0.626165 | H206: 69 | I206: =IF(G206<$Q$4,"tak","nie") -> nie | J206: 0.001131 | K206: 0.769562 | L206: 0.620705 | M206: 30 | N206: =IF(L206<$Q$4,"tak","nie") -> nie
B207: 5 | C207: -0.056197 | D207: -0.120802 | E207: 0.000503 | F207: 0.008798 | G207: 0.002472 | H207: 53 | I207: =IF(G207<$Q$4,"tak","nie") -> tak | J207: -0.012997 | K207: 0.002109 | L207: 0.005516 | M207: 28 | N207: =IF(L207<$Q$4,"tak","nie") -> tak
B208: 6 | C208: 0.059245 | D208: -0.010225 | E208: 0.002545 | F208: -0.010225 | G208: 0.003534 | H208: 51 | I208: =IF(G208<$Q$4,"tak","nie") -> tak | J208: 0.059245 | K208: -0.010225 | L208: 0.113155 | M208: 8 | N208: =IF(L208<$Q$4,"tak","nie") -> nie
B209: 7 | C209: -0.893621 | D209: 0.141519 | E209: 0.006379 | F209: 0.009219 | G209: 0.004 | H209: 78 | I209: =IF(G209<$Q$4,"tak","nie") -> tak | J209: 0.006379 | K209: -0.038481 | L209: 0.048101 | M209: 12 | N209: =IF(L209<$Q$4,"tak","nie") -> nie
B210: 8 | C210: -0.5743 | D210: 0.590025 | E210: -0.7633 | F210: 0.779025 | G210: 1.2443 | H210: 50 | I210: =IF(G210<$Q$4,"tak","nie") -> nie | J210: -0.772556 | K210: 0.791022 | L210: 1.248184 | M210: 36 | N210: =IF(L210<$Q$4,"tak","nie") -> nie
B211: 9 | C211: -0.839485 | D211: 0.021344 | E211: 0.003815 | F211: -0.002956 | G211: 0.000742 | H211: 62 | I211: =IF(G211<$Q$4,"tak","nie") -> tak | J211: 0.060515 | K211: 0.014144 | L211: 0.120863 | M211: 16 | N211: =IF(L211<$Q$4,"tak","nie") -> nie
...

Sheet Tabela 2
A1: Długość kroku | B1: Metoda Hooke’a-Jeevesa | G1: Metoda Rosenbrocka
B2: x1* | C2: x2* | D2: y* | E2: Liczba wywołań funkcji celu | F2: Liczba minimów globalnych | G2: x1* | H2: x2* | I2: y* | J2: Liczba wywołań funkcji celu | K2: Liczba minimów globalnych
A3: ='Tabela 1'!A3 -> 0.1 | B3: =AVERAGEIF('Tabela 1'!$I$3:$I$102,"tak",'Tabela 1'!E3:E102) -> -0.001373125 | C3: =AVERAGEIF('Tabela 1'!$I$3:$I$102,"tak",'Tabela 1'!F3:F102) -> 0.000194375 | D3: =AVERAGEIF('Tabela 1'!$I$3:$I$102,"tak",'Tabela 1'!G3:G102) -> 0.0045335 | E3: =AVERAGEIF('Tabela 1'!$I$3:$I$102,"tak",'Tabela 1'!H3:H102) -> 43.25 | F3: =COUNTIF('Tabela 1'!I3:I102,"tak") -> 16 | G3: =AVERAGEIF('Tabela 1'!$N$3:$N$102,"tak",'Tabela 1'!J3:J102) -> 0.0033571111 | H3: =AVERAGEIF('Tabela 1'!$N$3:$N$102,"tak",'Tabela 1'!K3:K102) -> -0.0027568889 | I3: =AVERAGEIF('Tabela 1'!$N$3:$N$102,"tak",'Tabela 1'!L3:L102) -> 0.0020172222 | J3: =AVERAGEIF('Tabela 1'!$N$3:$N$102,"tak",'Tabela 1'!M3:M102) -> 23.777778 | K3: =COUNTIF('Tabela 1'!N3:N102,"tak") -> 9
A4: ='Tabela 1'!A103 -> 0.5 | B4: =AVERAGEIF('Tabela 1'!$I$103:$I$202,"tak",'Tabela 1'!E103:E202) -> 0.00045621429 | C4: =AVERAGEIF('Tabela 1'!$I$103:$I$202,"tak",'Tabela 1'!F103:F202) -> 0.00024378571 | D4: =AVERAGEIF('Tabela 1'!$I$103:$I$202,"tak",'Tabela 1'!G103:G202) -> 0.00077814286 | E4: =AVERAGEIF('Tabela 1'!$I$103:$I$202,"tak",'Tabela 1'!H103:H202) -> 66.071429 | F4: =COUNTIF('Tabela 1'!I103:I202,"tak") -> 14 | G4: =AVERAGEIF('Tabela 1'!$N$103:$N$202,"tak",'Tabela 1'!J103:J202) -> 0.00035845455 | H4: =AVERAGEIF('Tabela 1'!$N$103:$N$202,"tak",'Tabela 1'!K103:K202) -> -0.00059381818 | I4: =AVERAGEIF('Tabela 1'!$N$103:$N$202,"tak",'Tabela 1'!L103:L202) -> 0.0020941818 | J4: =AVERAGEIF('Tabela 1'!$N$103:$N$202,"tak",'Tabela 1'!M103:M202) -> 36 | K4: =COUNTIF('Tabela 1'!N103:N202,"tak") -> 11
A5: ='Tabela 1'!A203 -> 0.9 | B5: =AVERAGEIF('Tabela 1'!$I$203:$I$302,"tak",'Tabela 1'!E203:E302) -> -0.00014643478 | C5: =AVERAGEIF('Tabela 1'!$I$203:$I$302,"tak",'Tabela 1'!F203:F302) -> 0.00011034783 | D5: =AVERAGEIF('Tabela 1'!$I$203:$I$302,"tak",'Tabela 1'!G203:G302) -> 0.0031217391 | E5: =AVERAGEIF('Tabela 1'!$I$203:$I$302,"tak",'Tabela 1'!H203:H302) -> 62.434783 | F5: =COUNTIF('Tabela 1'!I203:I302,"tak") -> 23 | G5: =AVERAGEIF('Tabela 1'!$N$203:$N$302,"tak",'Tabela 1'!J203:J302) -> -0.00059094737 | H5: =AVERAGEIF('Tabela 1'!$N$203:$N$302,"tak",'Tabela 1'!K203:K302) -> 0.002353 | I5: =AVERAGEIF('Tabela 1'!$N$203:$N$302,"tak",'Tabela 1'!L203:L302) -> 0.0032534211 | J5: =AVERAGEIF('Tabela 1'!$N$203:$N$302,"tak",'Tabela 1'!M203:M302) -> 29.368421 | K5: =COUNTIF('Tabela 1'!N203:N302,"tak") -> 19
I9: Liczba minimów globalnych
F10: Liczba wywołań funkcji celu | I10: HJ | J10: Rosen
F11: HJ | G11: Rosen | I11: 16 | J11: 9
F12: 43.25 | G12: 23.777778 | I12: 14 | J12: 11
F13: 66.071429 | G13: 36 | I13: 23 | J13: 19
F14: 62.434783 | G14: 29.368421

Sheet Wykres
A1: Nr iteracji | B1: Metoda Hooke’a-Jeevesa | D1: Metoda Rosenbrocka
B2: x1* | C2: x2* | D2: x1* | E2: x2*
A3: 0 | B3: 0.21 | C3: 0.37 | D3: 0.03 | E3: 0.37
A4: 1 | B4: -0.69 | C4: -0.53 | D4: 0.03 | E4: 0.19
A5: 2 | B5: -0.69 | C5: -0.53 | D5: 0.004544 | E5: 0.164544
A6: 3 | B6: -0.69 | C6: 0.01 | D6: 0.03 | E6: 0.139088
A7: 4 | B7: -0.69 | C7: 0.01 | D7: 0.03 | E7: 0.103088
A8: 5 | B8: -0.771 | C8: 0.01 | D8: 0.03 | E8: 0.063488
A9: 6 | B9: -0.771 | C9: 0.01 | D9: 0.0228 | E9: 0.063488
A10: 7 | D10: 0.019387 | E10: 0.02765
A11: 8 | D11: 0.015632 | E11: -0.011771
A12: … | D12: 0.014199 | E12: -0.011635

Sheet Tabela 3
A1: Długość kroku | B1: Metoda Hooke’a-Jeevesa | F1: Metoda Rosenbrocka
B2: k1* | C2: k2* | D2: Q* | E2: Liczba wywołań funkcji celu | F2: k1* | G2: k2* | H2: Q* | I2: Liczba wywołań funkcji celu
A3: 0.5 | B3: 3.001432 | C3: 10.819899 | D3: 373.65631 | E3: 212 | F3: 3.0023 | G3: 10.834834 | H3: 373.65632 | I3: 150
C10: 3.001432 | D10: 10.819899 | F10: 3.0023 | G10: 10.834834
F14: Liczba wywołań funkcji celu
F15: HJ | G15: Rosen
F16: 212 | G16: 150

Sheet Symulacja
A1: t | B1: Met. HJ | D1: Met. Rosen
B2: α | C2: ω | D2: α | E2: ω
A3: 0 | B3: 0 | C3: 0 | D3: 0 | E3: 0
A4: 1 | B4: 0.002172 | C4: 0.043062 | D4: 0.002173 | E4: 0.043073
A5: 2 | B5: 0.008538 | C5: 0.083888 | D5: 0.00854 | E5: 0.083907
A6: 3 | B6: 0.018877 | C6: 0.122535 | D6: 0.018881 | E6: 0.122558
A7: 4 | B7: 0.032974 | C7: 0.159059 | D7: 0.032981 | E7: 0.159083
A8: 5 | B8: 0.05062 | C8: 0.193518 | D8: 0.050629 | E8: 0.193542
A9: 6 | B9: 0.071611 | C9: 0.22597 | D9: 0.071622 | E9: 0.22599
A10: 7 | B10: 0.095749 | C10: 0.256471 | D10: 0.095762 | E10: 0.256485
A11: 8 | B11: 0.122842 | C11: 0.285077 | D11: 0.122856 | E11: 0.285084
A12: 9 | B12: 0.152703 | C12: 0.311847 | D12: 0.152717 | E12: 0.311845
A13: 10 | B13: 0.185152 | C13: 0.336835 | D13: 0.185165 | E13: 0.336823
A14: 11 | B14: 0.220013 | C14: 0.360098 | D14: 0.220024 | E14: 0.360074
... A30: 27 | B30: 0.98363 | C30: 0.540903 | D30: 0.983415 | E30: 0.540644
A31: 28 | B31: 1.03782 | C31: 0.542763 | D31: 1.037579 | E31: 0.542492 | H31: * | I31: do 560 kroku włącznie mamy stan nieustalony
A32: 29 | B32: 1.092154 | C32: 0.543785 | D32: 1.091885 | E32: 0.543503 | H32: * | I32: od 561 w góre jest stan ustalony
A33: 30 | B33: 1.146551 | C33: 0.54401 | D33: 1.146253 | E33: 0.543717
A34: 31 | B34: 1.200931 | C34: 0.543478 | D34: 1.200603 | E34: 0.543175
A35: 32 | B35: 1.255222 | C35: 0.542228 | D35: 1.254864 | E35: 0.541915
A36: 33 | B36: 1.309354 | C36: 0.540298 | D36: 1.308964 | E36: 0.539976
A37: 34 | B37: 1.36326 | C37: 0.537724 | D37: 1.362838 | E37: 0.537395
A38: 35 | B38: 1.416879 | C38: 0.534544 | D38: 1.416423 | E38: 0.534207
A39: 36 | B39: 1.47015 | C39: 0.530791 | D39: 1.46966 | E39: 0.530449
A40: 37 | B40: 1.523019 | C40: 0.526501 | D40: 1.522494 | E40: 0.526153
A41: 38 | B41: 1.575433 | C41: 0.521706 | D41: 1.574874 | E41: 0.521354
A42: 39 | B42: 1.627344 | C42: 0.516438 | D42: 1.62675 | E42: 0.516082
A43: 40 | B43: 1.678706 | C43: 0.510728 | D43: 1.678076 | E43: 0.51037
A44: 41 | B44: 1.729476 | C44: 0.504608 | D44: 1.72881 | E44: 0.504247
... A1003: 1000 | B1003: 3.141593 | C1003: 0 | D1003: 3.141593 | E1003: 0
